2018-06-29 11:14:13,438 [django.request:93] [base:get_response] [WARNING]- Not Found: /
2018-06-29 11:14:32,678 [HttpRunnerManager:45] [views:login] [INFO]- yinquanwang 登录成功
2018-06-29 11:14:33,058 [django.request:93] [base:get_response] [WARNING]- Not Found: /static/assets/js/commons.js
2018-06-29 11:14:33,499 [django.request:93] [base:get_response] [WARNING]- Not Found: /static/assets/js/commons.js
2018-06-29 11:14:58,797 [HttpRunnerManager:45] [views:login] [INFO]- yinquanwang 登录成功
2018-06-29 11:48:11,403 [HttpRunnerManager:151] [operation:add_case_data] [INFO]- 的用例添加成功: {'test': {'request': {'method': 'POST', 'url': ''}, 'name': '的'}}
2018-06-29 11:48:48,076 [HttpRunnerManager:45] [views:login] [INFO]- yinquanwang 登录成功
2018-07-02 13:34:18,047 [django.request:93] [base:get_response] [WARNING]- Not Found: /static/assets/css/css-index.css
2018-07-02 13:34:18,057 [django.request:93] [base:get_response] [WARNING]- Not Found: /static/assets/img/logo.png
2018-07-02 13:34:18,268 [django.request:93] [base:get_response] [WARNING]- Not Found: /static/assets/js/custom.js
2018-07-02 13:34:18,270 [django.request:93] [base:get_response] [WARNING]- Not Found: /static/assets/js/jquery.sticky.js
2018-07-02 13:34:18,276 [django.request:93] [base:get_response] [WARNING]- Not Found: /static/assets/js/wow.min.js
2018-07-02 13:34:18,278 [django.request:93] [base:get_response] [WARNING]- Not Found: /static/assets/js/owl.carousel.min.js
2018-07-02 13:34:18,296 [django.request:93] [base:get_response] [WARNING]- Not Found: /static/assets/img/bg.jpg
2018-07-02 13:34:18,299 [django.request:93] [base:get_response] [WARNING]- Not Found: /static/assets/img/loading.GIF
2018-07-02 13:34:18,352 [django.request:93] [base:get_response] [WARNING]- Not Found: /static/assets/js/custom.js
2018-07-02 13:34:18,364 [django.request:93] [base:get_response] [WARNING]- Not Found: /static/assets/js/jquery.sticky.js
2018-07-02 13:34:18,370 [django.request:93] [base:get_response] [WARNING]- Not Found: /static/assets/js/wow.min.js
2018-07-02 13:34:18,383 [django.request:93] [base:get_response] [WARNING]- Not Found: /static/assets/js/owl.carousel.min.js
2018-07-02 13:34:18,578 [django.request:93] [base:get_response] [WARNING]- Not Found: /static/assets/img/favicon.ico
2018-07-02 13:34:21,442 [django.request:93] [base:get_response] [WARNING]- Not Found: /static/assets/css/css-index.css
2018-07-02 13:34:21,445 [django.request:93] [base:get_response] [WARNING]- Not Found: /static/assets/js/custom.js
2018-07-02 13:34:21,449 [django.request:93] [base:get_response] [WARNING]- Not Found: /static/assets/img/logo.png
2018-07-02 13:34:21,484 [django.request:93] [base:get_response] [WARNING]- Not Found: /static/assets/js/jquery.sticky.js
2018-07-02 13:34:21,487 [django.request:93] [base:get_response] [WARNING]- Not Found: /static/assets/js/wow.min.js
2018-07-02 13:34:21,492 [django.request:93] [base:get_response] [WARNING]- Not Found: /static/assets/js/owl.carousel.min.js
2018-07-02 13:34:21,508 [django.request:93] [base:get_response] [WARNING]- Not Found: /static/assets/js/custom.js
2018-07-02 13:34:21,516 [django.request:93] [base:get_response] [WARNING]- Not Found: /static/assets/img/bg.jpg
2018-07-02 13:34:21,519 [django.request:93] [base:get_response] [WARNING]- Not Found: /static/assets/img/loading.GIF
2018-07-02 13:34:21,531 [django.request:93] [base:get_response] [WARNING]- Not Found: /static/assets/js/jquery.sticky.js
2018-07-02 13:34:21,540 [django.request:93] [base:get_response] [WARNING]- Not Found: /static/assets/js/wow.min.js
2018-07-02 13:34:21,545 [django.request:93] [base:get_response] [WARNING]- Not Found: /static/assets/js/owl.carousel.min.js
2018-07-02 13:34:22,424 [django.request:93] [base:get_response] [WARNING]- Not Found: /static/assets/css/css-index.css
2018-07-02 13:34:22,426 [django.request:93] [base:get_response] [WARNING]- Not Found: /static/assets/img/logo.png
2018-07-02 13:34:22,429 [django.request:93] [base:get_response] [WARNING]- Not Found: /static/assets/js/custom.js
2018-07-02 13:34:22,465 [django.request:93] [base:get_response] [WARNING]- Not Found: /static/assets/js/jquery.sticky.js
2018-07-02 13:34:22,466 [django.request:93] [base:get_response] [WARNING]- Not Found: /static/assets/js/wow.min.js
2018-07-02 13:34:22,468 [django.request:93] [base:get_response] [WARNING]- Not Found: /static/assets/js/owl.carousel.min.js
2018-07-02 13:34:22,480 [django.request:93] [base:get_response] [WARNING]- Not Found: /static/assets/js/custom.js
2018-07-02 13:34:22,483 [django.request:93] [base:get_response] [WARNING]- Not Found: /static/assets/img/bg.jpg
2018-07-02 13:34:22,490 [django.request:93] [base:get_response] [WARNING]- Not Found: /static/assets/img/loading.GIF
2018-07-02 13:34:22,498 [django.request:93] [base:get_response] [WARNING]- Not Found: /static/assets/js/jquery.sticky.js
2018-07-02 13:34:22,506 [django.request:93] [base:get_response] [WARNING]- Not Found: /static/assets/js/wow.min.js
2018-07-02 13:34:22,509 [django.request:93] [base:get_response] [WARNING]- Not Found: /static/assets/js/owl.carousel.min.js
2018-07-02 13:35:30,488 [HttpRunnerManager:45] [views:login] [INFO]- yinquanwang 登录成功
2018-07-02 13:48:28,352 [HttpRunnerManager:45] [views:login] [INFO]- yinquanwang 登录成功
2018-07-02 13:53:41,984 [django.request:118] [exception:handle_uncaught_exception] [ERROR]- Internal Server Error: /api/test_list/1/
Traceback (most recent call last):
  File "E:\Python35\lib\site-packages\django\core\handlers\exception.py", line 35, in inner
    response = get_response(request)
  File "E:\Python35\lib\site-packages\django\core\handlers\base.py", line 128, in _get_response
    response = self.process_exception_by_middleware(e, request)
  File "E:\Python35\lib\site-packages\django\core\handlers\base.py", line 126, in _get_response
    response = wrapped_callback(request, *callback_args, **callback_kwargs)
  File "D:/HttpRunnerManager\HttpRunnerManager\activator.py", line 15, in process
    result = fun(request, index) if index else fun(request)
  File "D:/HttpRunnerManager\ApiManager\views.py", line 379, in test_list
    filter_query = set_filter_session(request)
  File "D:/HttpRunnerManager\ApiManager\utils\common.py", line 439, in set_filter_session
    'belong_project': request.session['project'],
  File "E:\Python35\lib\site-packages\django\contrib\sessions\backends\base.py", line 55, in __getitem__
    return self._session[key]
KeyError: 'project'
2018-07-02 13:53:49,147 [django.request:118] [exception:handle_uncaught_exception] [ERROR]- Internal Server Error: /api/test_list/1/
Traceback (most recent call last):
  File "E:\Python35\lib\site-packages\django\core\handlers\exception.py", line 35, in inner
    response = get_response(request)
  File "E:\Python35\lib\site-packages\django\core\handlers\base.py", line 128, in _get_response
    response = self.process_exception_by_middleware(e, request)
  File "E:\Python35\lib\site-packages\django\core\handlers\base.py", line 126, in _get_response
    response = wrapped_callback(request, *callback_args, **callback_kwargs)
  File "D:/HttpRunnerManager\HttpRunnerManager\activator.py", line 15, in process
    result = fun(request, index) if index else fun(request)
  File "D:/HttpRunnerManager\ApiManager\views.py", line 379, in test_list
    filter_query = set_filter_session(request)
  File "D:/HttpRunnerManager\ApiManager\utils\common.py", line 439, in set_filter_session
    'belong_project': request.session['project'],
  File "E:\Python35\lib\site-packages\django\contrib\sessions\backends\base.py", line 55, in __getitem__
    return self._session[key]
KeyError: 'project'
2018-07-02 13:54:04,117 [HttpRunnerManager:78] [views:log_out] [INFO]- yinquanwang退出
2018-07-02 13:54:07,459 [HttpRunnerManager:45] [views:login] [INFO]- yinquanwang 登录成功
2018-07-02 13:57:09,661 [HttpRunnerManager:78] [views:log_out] [INFO]- yinquanwang退出
2018-07-02 13:57:11,824 [HttpRunnerManager:45] [views:login] [INFO]- yinquanwang 登录成功
2018-07-02 14:04:39,039 [HttpRunnerManager:78] [views:log_out] [INFO]- yinquanwang退出
2018-07-02 14:04:44,830 [HttpRunnerManager:45] [views:login] [INFO]- yinquanwang 登录成功
2018-07-02 14:04:54,650 [django.request:118] [exception:handle_uncaught_exception] [ERROR]- Internal Server Error: /api/test_list/1/
Traceback (most recent call last):
  File "E:\Python35\lib\site-packages\django\core\handlers\exception.py", line 35, in inner
    response = get_response(request)
  File "E:\Python35\lib\site-packages\django\core\handlers\base.py", line 128, in _get_response
    response = self.process_exception_by_middleware(e, request)
  File "E:\Python35\lib\site-packages\django\core\handlers\base.py", line 126, in _get_response
    response = wrapped_callback(request, *callback_args, **callback_kwargs)
  File "D:\HttpRunnerManager\HttpRunnerManager\activator.py", line 15, in process
    result = fun(request, index) if index else fun(request)
  File "D:\HttpRunnerManager\ApiManager\views.py", line 379, in test_list
    filter_query = set_filter_session(request)
  File "D:\HttpRunnerManager\ApiManager\utils\common.py", line 432, in set_filter_session
    request.session['module'] = ModuleInfo.objects.get(id=request.POST.get('module')).module_name
  File "E:\Python35\lib\site-packages\django\db\models\manager.py", line 82, in manager_method
    return getattr(self.get_queryset(), name)(*args, **kwargs)
  File "E:\Python35\lib\site-packages\django\db\models\query.py", line 394, in get
    clone = self.filter(*args, **kwargs)
  File "E:\Python35\lib\site-packages\django\db\models\query.py", line 836, in filter
    return self._filter_or_exclude(False, *args, **kwargs)
  File "E:\Python35\lib\site-packages\django\db\models\query.py", line 854, in _filter_or_exclude
    clone.query.add_q(Q(*args, **kwargs))
  File "E:\Python35\lib\site-packages\django\db\models\sql\query.py", line 1253, in add_q
    clause, _ = self._add_q(q_object, self.used_aliases)
  File "E:\Python35\lib\site-packages\django\db\models\sql\query.py", line 1277, in _add_q
    split_subq=split_subq,
  File "E:\Python35\lib\site-packages\django\db\models\sql\query.py", line 1215, in build_filter
    condition = self.build_lookup(lookups, col, value)
  File "E:\Python35\lib\site-packages\django\db\models\sql\query.py", line 1085, in build_lookup
    lookup = lookup_class(lhs, rhs)
  File "E:\Python35\lib\site-packages\django\db\models\lookups.py", line 18, in __init__
    self.rhs = self.get_prep_lookup()
  File "E:\Python35\lib\site-packages\django\db\models\lookups.py", line 68, in get_prep_lookup
    return self.lhs.output_field.get_prep_value(self.rhs)
  File "E:\Python35\lib\site-packages\django\db\models\fields\__init__.py", line 947, in get_prep_value
    return int(value)
ValueError: invalid literal for int() with base 10: ''
2018-07-02 14:06:02,565 [django.request:118] [exception:handle_uncaught_exception] [ERROR]- Internal Server Error: /api/config_list/1/
Traceback (most recent call last):
  File "E:\Python35\lib\site-packages\django\core\handlers\exception.py", line 35, in inner
    response = get_response(request)
  File "E:\Python35\lib\site-packages\django\core\handlers\base.py", line 128, in _get_response
    response = self.process_exception_by_middleware(e, request)
  File "E:\Python35\lib\site-packages\django\core\handlers\base.py", line 126, in _get_response
    response = wrapped_callback(request, *callback_args, **callback_kwargs)
  File "D:\HttpRunnerManager\HttpRunnerManager\activator.py", line 15, in process
    result = fun(request, index) if index else fun(request)
  File "D:\HttpRunnerManager\ApiManager\views.py", line 413, in config_list
    filter_query = set_filter_session(request)
  File "D:\HttpRunnerManager\ApiManager\utils\common.py", line 432, in set_filter_session
    request.session['module'] = ModuleInfo.objects.get(id=request.POST.get('module')).module_name
  File "E:\Python35\lib\site-packages\django\db\models\manager.py", line 82, in manager_method
    return getattr(self.get_queryset(), name)(*args, **kwargs)
  File "E:\Python35\lib\site-packages\django\db\models\query.py", line 394, in get
    clone = self.filter(*args, **kwargs)
  File "E:\Python35\lib\site-packages\django\db\models\query.py", line 836, in filter
    return self._filter_or_exclude(False, *args, **kwargs)
  File "E:\Python35\lib\site-packages\django\db\models\query.py", line 854, in _filter_or_exclude
    clone.query.add_q(Q(*args, **kwargs))
  File "E:\Python35\lib\site-packages\django\db\models\sql\query.py", line 1253, in add_q
    clause, _ = self._add_q(q_object, self.used_aliases)
  File "E:\Python35\lib\site-packages\django\db\models\sql\query.py", line 1277, in _add_q
    split_subq=split_subq,
  File "E:\Python35\lib\site-packages\django\db\models\sql\query.py", line 1215, in build_filter
    condition = self.build_lookup(lookups, col, value)
  File "E:\Python35\lib\site-packages\django\db\models\sql\query.py", line 1085, in build_lookup
    lookup = lookup_class(lhs, rhs)
  File "E:\Python35\lib\site-packages\django\db\models\lookups.py", line 18, in __init__
    self.rhs = self.get_prep_lookup()
  File "E:\Python35\lib\site-packages\django\db\models\lookups.py", line 68, in get_prep_lookup
    return self.lhs.output_field.get_prep_value(self.rhs)
  File "E:\Python35\lib\site-packages\django\db\models\fields\__init__.py", line 947, in get_prep_value
    return int(value)
ValueError: invalid literal for int() with base 10: ''
2018-07-02 14:24:14,328 [HttpRunnerManager:78] [views:log_out] [INFO]- yinquanwang退出
2018-07-02 14:24:16,921 [HttpRunnerManager:45] [views:login] [INFO]- yinquanwang 登录成功
2018-07-02 14:27:17,963 [django.request:118] [exception:handle_uncaught_exception] [ERROR]- Internal Server Error: /api/project_list/1/
Traceback (most recent call last):
  File "E:\Python35\lib\site-packages\django\template\base.py", line 475, in parse
    compile_func = self.tags[command]
KeyError: 'endif'

During handling of the above exception, another exception occurred:

Traceback (most recent call last):
  File "E:\Python35\lib\site-packages\django\core\handlers\exception.py", line 35, in inner
    response = get_response(request)
  File "E:\Python35\lib\site-packages\django\core\handlers\base.py", line 128, in _get_response
    response = self.process_exception_by_middleware(e, request)
  File "E:\Python35\lib\site-packages\django\core\handlers\base.py", line 126, in _get_response
    response = wrapped_callback(request, *callback_args, **callback_kwargs)
  File "D:\HttpRunnerManager\HttpRunnerManager\activator.py", line 15, in process
    result = fun(request, index) if index else fun(request)
  File "D:\HttpRunnerManager\ApiManager\views.py", line 323, in project_list
    return render_to_response('project_list.html', manage_info)
  File "E:\Python35\lib\site-packages\django\shortcuts.py", line 27, in render_to_response
    content = loader.render_to_string(template_name, context, using=using)
  File "E:\Python35\lib\site-packages\django\template\loader.py", line 61, in render_to_string
    template = get_template(template_name, using=using)
  File "E:\Python35\lib\site-packages\django\template\loader.py", line 15, in get_template
    return engine.get_template(template_name)
  File "E:\Python35\lib\site-packages\django\template\backends\django.py", line 34, in get_template
    return Template(self.engine.get_template(template_name), self)
  File "E:\Python35\lib\site-packages\django\template\engine.py", line 144, in get_template
    template, origin = self.find_template(template_name)
  File "E:\Python35\lib\site-packages\django\template\engine.py", line 126, in find_template
    template = loader.get_template(name, skip=skip)
  File "E:\Python35\lib\site-packages\django\template\loaders\base.py", line 30, in get_template
    contents, origin, origin.template_name, self.engine,
  File "E:\Python35\lib\site-packages\django\template\base.py", line 160, in __init__
    self.nodelist = self.compile_nodelist()
  File "E:\Python35\lib\site-packages\django\template\base.py", line 198, in compile_nodelist
    return parser.parse()
  File "E:\Python35\lib\site-packages\django\template\base.py", line 483, in parse
    raise self.error(token, e)
  File "E:\Python35\lib\site-packages\django\template\base.py", line 481, in parse
    compiled_result = compile_func(self, token)
  File "E:\Python35\lib\site-packages\django\template\loader_tags.py", line 290, in do_extends
    nodelist = parser.parse()
  File "E:\Python35\lib\site-packages\django\template\base.py", line 483, in parse
    raise self.error(token, e)
  File "E:\Python35\lib\site-packages\django\template\base.py", line 481, in parse
    compiled_result = compile_func(self, token)
  File "E:\Python35\lib\site-packages\django\template\loader_tags.py", line 233, in do_block
    nodelist = parser.parse(('endblock',))
  File "E:\Python35\lib\site-packages\django\template\base.py", line 477, in parse
    self.invalid_block_tag(token, command, parse_until)
  File "E:\Python35\lib\site-packages\django\template\base.py", line 533, in invalid_block_tag
    get_text_list(["'%s'" % p for p in parse_until], 'or'),
django.template.exceptions.TemplateSyntaxError: Invalid block tag on line 176: 'endif', expected 'endblock'. Did you forget to register or load this tag?
2018-07-02 14:27:44,949 [django.request:118] [exception:handle_uncaught_exception] [ERROR]- Internal Server Error: /api/project_list/1/
Traceback (most recent call last):
  File "E:\Python35\lib\site-packages\django\template\base.py", line 475, in parse
    compile_func = self.tags[command]
KeyError: 'endif'

During handling of the above exception, another exception occurred:

Traceback (most recent call last):
  File "E:\Python35\lib\site-packages\django\core\handlers\exception.py", line 35, in inner
    response = get_response(request)
  File "E:\Python35\lib\site-packages\django\core\handlers\base.py", line 128, in _get_response
    response = self.process_exception_by_middleware(e, request)
  File "E:\Python35\lib\site-packages\django\core\handlers\base.py", line 126, in _get_response
    response = wrapped_callback(request, *callback_args, **callback_kwargs)
  File "D:\HttpRunnerManager\HttpRunnerManager\activator.py", line 15, in process
    result = fun(request, index) if index else fun(request)
  File "D:\HttpRunnerManager\ApiManager\views.py", line 323, in project_list
    return render_to_response('project_list.html', manage_info)
  File "E:\Python35\lib\site-packages\django\shortcuts.py", line 27, in render_to_response
    content = loader.render_to_string(template_name, context, using=using)
  File "E:\Python35\lib\site-packages\django\template\loader.py", line 61, in render_to_string
    template = get_template(template_name, using=using)
  File "E:\Python35\lib\site-packages\django\template\loader.py", line 15, in get_template
    return engine.get_template(template_name)
  File "E:\Python35\lib\site-packages\django\template\backends\django.py", line 34, in get_template
    return Template(self.engine.get_template(template_name), self)
  File "E:\Python35\lib\site-packages\django\template\engine.py", line 144, in get_template
    template, origin = self.find_template(template_name)
  File "E:\Python35\lib\site-packages\django\template\engine.py", line 126, in find_template
    template = loader.get_template(name, skip=skip)
  File "E:\Python35\lib\site-packages\django\template\loaders\base.py", line 30, in get_template
    contents, origin, origin.template_name, self.engine,
  File "E:\Python35\lib\site-packages\django\template\base.py", line 160, in __init__
    self.nodelist = self.compile_nodelist()
  File "E:\Python35\lib\site-packages\django\template\base.py", line 198, in compile_nodelist
    return parser.parse()
  File "E:\Python35\lib\site-packages\django\template\base.py", line 483, in parse
    raise self.error(token, e)
  File "E:\Python35\lib\site-packages\django\template\base.py", line 481, in parse
    compiled_result = compile_func(self, token)
  File "E:\Python35\lib\site-packages\django\template\loader_tags.py", line 290, in do_extends
    nodelist = parser.parse()
  File "E:\Python35\lib\site-packages\django\template\base.py", line 483, in parse
    raise self.error(token, e)
  File "E:\Python35\lib\site-packages\django\template\base.py", line 481, in parse
    compiled_result = compile_func(self, token)
  File "E:\Python35\lib\site-packages\django\template\loader_tags.py", line 233, in do_block
    nodelist = parser.parse(('endblock',))
  File "E:\Python35\lib\site-packages\django\template\base.py", line 477, in parse
    self.invalid_block_tag(token, command, parse_until)
  File "E:\Python35\lib\site-packages\django\template\base.py", line 533, in invalid_block_tag
    get_text_list(["'%s'" % p for p in parse_until], 'or'),
django.template.exceptions.TemplateSyntaxError: Invalid block tag on line 176: 'endif', expected 'endblock'. Did you forget to register or load this tag?
2018-07-02 14:27:47,983 [django.request:118] [exception:handle_uncaught_exception] [ERROR]- Internal Server Error: /api/project_list/1/
Traceback (most recent call last):
  File "E:\Python35\lib\site-packages\django\template\base.py", line 475, in parse
    compile_func = self.tags[command]
KeyError: 'endif'

During handling of the above exception, another exception occurred:

Traceback (most recent call last):
  File "E:\Python35\lib\site-packages\django\core\handlers\exception.py", line 35, in inner
    response = get_response(request)
  File "E:\Python35\lib\site-packages\django\core\handlers\base.py", line 128, in _get_response
    response = self.process_exception_by_middleware(e, request)
  File "E:\Python35\lib\site-packages\django\core\handlers\base.py", line 126, in _get_response
    response = wrapped_callback(request, *callback_args, **callback_kwargs)
  File "D:\HttpRunnerManager\HttpRunnerManager\activator.py", line 15, in process
    result = fun(request, index) if index else fun(request)
  File "D:\HttpRunnerManager\ApiManager\views.py", line 323, in project_list
    return render_to_response('project_list.html', manage_info)
  File "E:\Python35\lib\site-packages\django\shortcuts.py", line 27, in render_to_response
    content = loader.render_to_string(template_name, context, using=using)
  File "E:\Python35\lib\site-packages\django\template\loader.py", line 61, in render_to_string
    template = get_template(template_name, using=using)
  File "E:\Python35\lib\site-packages\django\template\loader.py", line 15, in get_template
    return engine.get_template(template_name)
  File "E:\Python35\lib\site-packages\django\template\backends\django.py", line 34, in get_template
    return Template(self.engine.get_template(template_name), self)
  File "E:\Python35\lib\site-packages\django\template\engine.py", line 144, in get_template
    template, origin = self.find_template(template_name)
  File "E:\Python35\lib\site-packages\django\template\engine.py", line 126, in find_template
    template = loader.get_template(name, skip=skip)
  File "E:\Python35\lib\site-packages\django\template\loaders\base.py", line 30, in get_template
    contents, origin, origin.template_name, self.engine,
  File "E:\Python35\lib\site-packages\django\template\base.py", line 160, in __init__
    self.nodelist = self.compile_nodelist()
  File "E:\Python35\lib\site-packages\django\template\base.py", line 198, in compile_nodelist
    return parser.parse()
  File "E:\Python35\lib\site-packages\django\template\base.py", line 483, in parse
    raise self.error(token, e)
  File "E:\Python35\lib\site-packages\django\template\base.py", line 481, in parse
    compiled_result = compile_func(self, token)
  File "E:\Python35\lib\site-packages\django\template\loader_tags.py", line 290, in do_extends
    nodelist = parser.parse()
  File "E:\Python35\lib\site-packages\django\template\base.py", line 483, in parse
    raise self.error(token, e)
  File "E:\Python35\lib\site-packages\django\template\base.py", line 481, in parse
    compiled_result = compile_func(self, token)
  File "E:\Python35\lib\site-packages\django\template\loader_tags.py", line 233, in do_block
    nodelist = parser.parse(('endblock',))
  File "E:\Python35\lib\site-packages\django\template\base.py", line 477, in parse
    self.invalid_block_tag(token, command, parse_until)
  File "E:\Python35\lib\site-packages\django\template\base.py", line 533, in invalid_block_tag
    get_text_list(["'%s'" % p for p in parse_until], 'or'),
django.template.exceptions.TemplateSyntaxError: Invalid block tag on line 176: 'endif', expected 'endblock'. Did you forget to register or load this tag?
2018-07-02 14:28:16,257 [HttpRunnerManager:78] [views:log_out] [INFO]- yinquanwang退出
2018-07-02 14:28:18,192 [HttpRunnerManager:45] [views:login] [INFO]- yinquanwang 登录成功
2018-07-02 14:37:16,138 [django.request:118] [exception:handle_uncaught_exception] [ERROR]- Internal Server Error: /api/project_list/1/
Traceback (most recent call last):
  File "E:\Python35\lib\site-packages\django\core\handlers\exception.py", line 35, in inner
    response = get_response(request)
  File "E:\Python35\lib\site-packages\django\core\handlers\base.py", line 128, in _get_response
    response = self.process_exception_by_middleware(e, request)
  File "E:\Python35\lib\site-packages\django\core\handlers\base.py", line 126, in _get_response
    response = wrapped_callback(request, *callback_args, **callback_kwargs)
  File "D:\HttpRunnerManager\HttpRunnerManager\activator.py", line 15, in process
    result = fun(request, index) if index else fun(request)
  File "D:\HttpRunnerManager\ApiManager\views.py", line 311, in project_list
    filter_query = set_filter_session(request)
  File "D:\HttpRunnerManager\ApiManager\utils\common.py", line 442, in set_filter_session
    'belong_project': request.session['project'],
  File "E:\Python35\lib\site-packages\django\contrib\sessions\backends\base.py", line 55, in __getitem__
    return self._session[key]
KeyError: 'project'
2018-07-02 14:37:20,563 [django.request:118] [exception:handle_uncaught_exception] [ERROR]- Internal Server Error: /api/project_list/1/
Traceback (most recent call last):
  File "E:\Python35\lib\site-packages\django\core\handlers\exception.py", line 35, in inner
    response = get_response(request)
  File "E:\Python35\lib\site-packages\django\core\handlers\base.py", line 128, in _get_response
    response = self.process_exception_by_middleware(e, request)
  File "E:\Python35\lib\site-packages\django\core\handlers\base.py", line 126, in _get_response
    response = wrapped_callback(request, *callback_args, **callback_kwargs)
  File "D:\HttpRunnerManager\HttpRunnerManager\activator.py", line 15, in process
    result = fun(request, index) if index else fun(request)
  File "D:\HttpRunnerManager\ApiManager\views.py", line 311, in project_list
    filter_query = set_filter_session(request)
  File "D:\HttpRunnerManager\ApiManager\utils\common.py", line 442, in set_filter_session
    'belong_project': request.session['project'],
  File "E:\Python35\lib\site-packages\django\contrib\sessions\backends\base.py", line 55, in __getitem__
    return self._session[key]
KeyError: 'project'
2018-07-02 14:37:24,899 [HttpRunnerManager:78] [views:log_out] [INFO]- yinquanwang退出
2018-07-02 14:37:26,773 [HttpRunnerManager:45] [views:login] [INFO]- yinquanwang 登录成功
2018-07-02 14:37:30,837 [django.request:118] [exception:handle_uncaught_exception] [ERROR]- Internal Server Error: /api/add_case/
Traceback (most recent call last):
  File "E:\Python35\lib\site-packages\django\core\handlers\exception.py", line 35, in inner
    response = get_response(request)
  File "E:\Python35\lib\site-packages\django\core\handlers\base.py", line 128, in _get_response
    response = self.process_exception_by_middleware(e, request)
  File "E:\Python35\lib\site-packages\django\core\handlers\base.py", line 126, in _get_response
    response = wrapped_callback(request, *callback_args, **callback_kwargs)
  File "D:\HttpRunnerManager\HttpRunnerManager\activator.py", line 15, in process
    result = fun(request, index) if index else fun(request)
  File "D:\HttpRunnerManager\ApiManager\views.py", line 170, in add_case
    msg = case_info_logic(**testcase_info)
  File "D:\HttpRunnerManager\ApiManager\utils\common.py", line 210, in case_info_logic
    test = kwargs.pop('test')
KeyError: 'test'
2018-07-02 14:37:33,775 [django.request:118] [exception:handle_uncaught_exception] [ERROR]- Internal Server Error: /api/add_case/
Traceback (most recent call last):
  File "E:\Python35\lib\site-packages\django\core\handlers\exception.py", line 35, in inner
    response = get_response(request)
  File "E:\Python35\lib\site-packages\django\core\handlers\base.py", line 128, in _get_response
    response = self.process_exception_by_middleware(e, request)
  File "E:\Python35\lib\site-packages\django\core\handlers\base.py", line 126, in _get_response
    response = wrapped_callback(request, *callback_args, **callback_kwargs)
  File "D:\HttpRunnerManager\HttpRunnerManager\activator.py", line 15, in process
    result = fun(request, index) if index else fun(request)
  File "D:\HttpRunnerManager\ApiManager\views.py", line 170, in add_case
    msg = case_info_logic(**testcase_info)
  File "D:\HttpRunnerManager\ApiManager\utils\common.py", line 210, in case_info_logic
    test = kwargs.pop('test')
KeyError: 'test'
2018-07-02 14:39:25,603 [HttpRunnerManager:78] [views:log_out] [INFO]- yinquanwang退出
2018-07-02 14:39:27,918 [HttpRunnerManager:45] [views:login] [INFO]- yinquanwang 登录成功
2018-07-02 14:43:42,829 [HttpRunnerManager:78] [views:log_out] [INFO]- yinquanwang退出
2018-07-02 14:43:44,932 [HttpRunnerManager:45] [views:login] [INFO]- yinquanwang 登录成功
2018-07-02 14:47:52,728 [HttpRunnerManager:78] [views:log_out] [INFO]- yinquanwang退出
2018-07-02 14:47:54,981 [HttpRunnerManager:45] [views:login] [INFO]- yinquanwang 登录成功
2018-07-02 14:55:50,890 [HttpRunnerManager:78] [views:log_out] [INFO]- yinquanwang退出
2018-07-02 14:55:53,036 [HttpRunnerManager:45] [views:login] [INFO]- yinquanwang 登录成功
2018-07-02 14:57:17,859 [django.request:118] [exception:handle_uncaught_exception] [ERROR]- Internal Server Error: /api/module_list/1/
Traceback (most recent call last):
  File "E:\Python35\lib\site-packages\django\core\handlers\exception.py", line 35, in inner
    response = get_response(request)
  File "E:\Python35\lib\site-packages\django\core\handlers\base.py", line 128, in _get_response
    response = self.process_exception_by_middleware(e, request)
  File "E:\Python35\lib\site-packages\django\core\handlers\base.py", line 126, in _get_response
    response = wrapped_callback(request, *callback_args, **callback_kwargs)
  File "D:\HttpRunnerManager\HttpRunnerManager\activator.py", line 15, in process
    result = fun(request, index) if index else fun(request)
  File "D:\HttpRunnerManager\ApiManager\views.py", line 345, in module_list
    filter_query = set_filter_session(request)
  File "D:\HttpRunnerManager\ApiManager\utils\common.py", line 433, in set_filter_session
    request.session['module'] = ModuleInfo.objects.get(id=request.POST.get('module')).module_name
  File "E:\Python35\lib\site-packages\django\db\models\manager.py", line 82, in manager_method
    return getattr(self.get_queryset(), name)(*args, **kwargs)
  File "E:\Python35\lib\site-packages\django\db\models\query.py", line 394, in get
    clone = self.filter(*args, **kwargs)
  File "E:\Python35\lib\site-packages\django\db\models\query.py", line 836, in filter
    return self._filter_or_exclude(False, *args, **kwargs)
  File "E:\Python35\lib\site-packages\django\db\models\query.py", line 854, in _filter_or_exclude
    clone.query.add_q(Q(*args, **kwargs))
  File "E:\Python35\lib\site-packages\django\db\models\sql\query.py", line 1253, in add_q
    clause, _ = self._add_q(q_object, self.used_aliases)
  File "E:\Python35\lib\site-packages\django\db\models\sql\query.py", line 1277, in _add_q
    split_subq=split_subq,
  File "E:\Python35\lib\site-packages\django\db\models\sql\query.py", line 1215, in build_filter
    condition = self.build_lookup(lookups, col, value)
  File "E:\Python35\lib\site-packages\django\db\models\sql\query.py", line 1085, in build_lookup
    lookup = lookup_class(lhs, rhs)
  File "E:\Python35\lib\site-packages\django\db\models\lookups.py", line 18, in __init__
    self.rhs = self.get_prep_lookup()
  File "E:\Python35\lib\site-packages\django\db\models\lookups.py", line 68, in get_prep_lookup
    return self.lhs.output_field.get_prep_value(self.rhs)
  File "E:\Python35\lib\site-packages\django\db\models\fields\__init__.py", line 947, in get_prep_value
    return int(value)
ValueError: invalid literal for int() with base 10: '用例_quant_login_out(登入登出)'
2018-07-02 14:59:50,449 [HttpRunnerManager:78] [views:log_out] [INFO]- yinquanwang退出
2018-07-02 14:59:52,333 [HttpRunnerManager:45] [views:login] [INFO]- yinquanwang 登录成功
2018-12-03 16:59:15,275 [django.request:93] [base:get_response] [WARNING]- Not Found: /
2018-12-03 16:59:46,961 [django.request:93] [base:get_response] [WARNING]- Not Found: /dashboard
2018-12-03 17:01:50,483 [HttpRunnerManager:60] [views:login] [INFO]- admin 登录失败, 请检查用户名或者密码
2018-12-03 17:01:57,993 [HttpRunnerManager:60] [views:login] [INFO]- admin 登录失败, 请检查用户名或者密码
2018-12-03 17:02:37,371 [HttpRunnerManager:29] [operation:add_register_data] [DEBUG]- admin 已被其他用户注册
2018-12-03 17:04:08,412 [HttpRunnerManager:55] [views:login] [INFO]- admin 登录成功
2018-12-03 17:47:17,008 [HttpRunnerManager:60] [views:login] [INFO]- admin 登录失败, 请检查用户名或者密码
2018-12-03 17:47:20,483 [HttpRunnerManager:60] [views:login] [INFO]- admin 登录失败, 请检查用户名或者密码
2018-12-03 17:47:33,248 [HttpRunnerManager:55] [views:login] [INFO]- admin 登录成功
2018-12-03 18:12:34,282 [HttpRunnerManager:60] [views:login] [INFO]- admin 登录失败, 请检查用户名或者密码
2018-12-03 18:12:43,344 [HttpRunnerManager:55] [views:login] [INFO]- admin 登录成功
2018-12-03 18:13:39,134 [django.request:93] [base:get_response] [WARNING]- Not Found: /
2018-12-03 18:14:47,397 [django.request:93] [base:get_response] [WARNING]- Not Found: /
2018-12-03 18:14:50,545 [django.request:93] [base:get_response] [WARNING]- Not Found: /
2018-12-06 18:50:19,193 [django.request:228] [log:log_response] [WARNING]- Not Found: /
2018-12-06 18:51:06,232 [django.request:228] [log:log_response] [WARNING]- Not Found: /
2018-12-06 18:51:23,257 [django.request:228] [log:log_response] [WARNING]- Not Found: /dashboard
2018-12-06 18:54:05,006 [HttpRunnerManager:55] [views:login] [INFO]- admin 登录成功
2018-12-13 10:28:05,144 [django.request:228] [log:log_response] [WARNING]- Not Found: /dashboard
2018-12-13 10:28:59,844 [django.request:228] [log:log_response] [WARNING]- Not Found: /dashboard
2018-12-13 10:32:05,770 [HttpRunnerManager:55] [views:login] [INFO]- admin 登录成功
2018-12-13 10:42:16,065 [HttpRunnerManager:55] [views:login] [INFO]- admin 登录成功
2018-12-13 10:42:20,654 [HttpRunnerManager:89] [views:log_out] [INFO]- admin退出
2018-12-13 10:42:32,243 [HttpRunnerManager:60] [views:login] [INFO]- shadowmimosa 登录失败, 请检查用户名或者密码
2018-12-13 10:42:45,358 [HttpRunnerManager:60] [views:login] [INFO]- shadowmimosa 登录失败, 请检查用户名或者密码
2018-12-13 10:42:52,109 [HttpRunnerManager:55] [views:login] [INFO]- admin 登录成功
2018-12-18 23:02:48,163 [django.request:228] [log:log_response] [WARNING]- Not Found: /
2018-12-18 23:03:21,459 [django.request:228] [log:log_response] [ERROR]- Internal Server Error: /api/1/
Traceback (most recent call last):
  File "C:\Users\ShadowMimosa\AppData\Local\Programs\Python\Python37\lib\site-packages\django\core\handlers\exception.py", line 34, in inner
    response = get_response(request)
  File "C:\Users\ShadowMimosa\AppData\Local\Programs\Python\Python37\lib\site-packages\django\core\handlers\base.py", line 126, in _get_response
    response = self.process_exception_by_middleware(e, request)
  File "C:\Users\ShadowMimosa\AppData\Local\Programs\Python\Python37\lib\site-packages\django\core\handlers\base.py", line 124, in _get_response
    response = wrapped_callback(request, *callback_args, **callback_kwargs)
  File "C:\Users\ShadowMimosa\Documents\GitRepository\HttpRunnerManager\HttpRunnerManager\activator.py", line 12, in process
    fun = getattr(view, fun)
AttributeError: module 'ApiManager.views' has no attribute '1'
2018-12-18 23:03:56,209 [django.request:228] [log:log_response] [ERROR]- Internal Server Error: /apimanager/register/
Traceback (most recent call last):
  File "C:\Users\ShadowMimosa\AppData\Local\Programs\Python\Python37\lib\site-packages\django\core\handlers\exception.py", line 34, in inner
    response = get_response(request)
  File "C:\Users\ShadowMimosa\AppData\Local\Programs\Python\Python37\lib\site-packages\django\core\handlers\base.py", line 126, in _get_response
    response = self.process_exception_by_middleware(e, request)
  File "C:\Users\ShadowMimosa\AppData\Local\Programs\Python\Python37\lib\site-packages\django\core\handlers\base.py", line 124, in _get_response
    response = wrapped_callback(request, *callback_args, **callback_kwargs)
  File "C:\Users\ShadowMimosa\Documents\GitRepository\HttpRunnerManager\HttpRunnerManager\activator.py", line 10, in process
    app = __import__("%s.views" % app)
ModuleNotFoundError: No module named 'apimanager'
2018-12-18 23:05:13,433 [HttpRunnerManager:55] [views:login] [INFO]- admin 登录成功
2018-12-20 00:44:32,756 [HttpRunnerManager:60] [views:login] [INFO]-  登录失败, 请检查用户名或者密码
2018-12-20 00:44:47,018 [HttpRunnerManager:60] [views:login] [INFO]-  登录失败, 请检查用户名或者密码
2018-12-20 00:44:49,650 [HttpRunnerManager:60] [views:login] [INFO]-  登录失败, 请检查用户名或者密码
2018-12-20 00:44:50,986 [HttpRunnerManager:60] [views:login] [INFO]-  登录失败, 请检查用户名或者密码
2018-12-20 00:44:51,833 [HttpRunnerManager:60] [views:login] [INFO]-  登录失败, 请检查用户名或者密码
2018-12-20 00:45:01,764 [HttpRunnerManager:60] [views:login] [INFO]-  登录失败, 请检查用户名或者密码
2018-12-20 00:45:05,796 [HttpRunnerManager:60] [views:login] [INFO]-  登录失败, 请检查用户名或者密码
2018-12-20 10:07:29,014 [HttpRunnerManager:60] [views:login] [INFO]-  登录失败, 请检查用户名或者密码
2018-12-20 10:07:45,491 [HttpRunnerManager:60] [views:login] [INFO]-  登录失败, 请检查用户名或者密码
2018-12-20 10:07:52,719 [HttpRunnerManager:60] [views:login] [INFO]-  登录失败, 请检查用户名或者密码
2018-12-20 11:10:44,935 [HttpRunnerManager:60] [views:login] [INFO]-  登录失败, 请检查用户名或者密码
2018-12-20 11:10:46,449 [HttpRunnerManager:60] [views:login] [INFO]-  登录失败, 请检查用户名或者密码
2018-12-20 14:45:19,324 [HttpRunnerManager:60] [views:login] [INFO]-  登录失败, 请检查用户名或者密码
2018-12-20 14:45:22,285 [HttpRunnerManager:60] [views:login] [INFO]-  登录失败, 请检查用户名或者密码
2018-12-20 14:45:24,902 [HttpRunnerManager:60] [views:login] [INFO]-  登录失败, 请检查用户名或者密码
2018-12-20 14:45:25,965 [HttpRunnerManager:60] [views:login] [INFO]-  登录失败, 请检查用户名或者密码
2018-12-20 14:45:26,717 [HttpRunnerManager:60] [views:login] [INFO]-  登录失败, 请检查用户名或者密码
2018-12-20 14:45:30,399 [HttpRunnerManager:60] [views:login] [INFO]-  登录失败, 请检查用户名或者密码
2018-12-20 14:45:34,078 [HttpRunnerManager:60] [views:login] [INFO]-  登录失败, 请检查用户名或者密码
2018-12-20 22:04:11,805 [HttpRunnerManager:60] [views:login] [INFO]-  登录失败, 请检查用户名或者密码
2018-12-20 22:04:25,539 [HttpRunnerManager:60] [views:login] [INFO]- joyrun 登录失败, 请检查用户名或者密码
2018-12-20 22:04:51,093 [HttpRunnerManager:55] [views:login] [INFO]- admin 登录成功
2018-12-20 22:53:34,173 [HttpRunnerManager:55] [views:login] [INFO]- admin 登录成功
2018-12-20 22:53:51,876 [HttpRunnerManager:55] [views:login] [INFO]- admin 登录成功
2018-12-21 10:15:17,141 [HttpRunnerManager:55] [views:login] [INFO]- admin 登录成功
2018-12-21 10:25:58,257 [HttpRunnerManager:62] [operation:add_project_data] [INFO]- 项目添加成功：{'project_name': 'tumblr likes', 'responsible_name': 'admin', 'test_user': 'admin', 'dev_user': 'admin', 'publish_app': 'tumblr', 'simple_desc': "Retrieve tumblr's likes", 'other_desc': 'Down'}
2018-12-21 10:26:27,576 [django.request:228] [log:log_response] [ERROR]- Internal Server Error: /api/run_test/
Traceback (most recent call last):
  File "C:\Users\ShadowMimosa\AppData\Local\Programs\Python\Python37\lib\site-packages\django\core\handlers\exception.py", line 34, in inner
    response = get_response(request)
  File "C:\Users\ShadowMimosa\AppData\Local\Programs\Python\Python37\lib\site-packages\django\core\handlers\base.py", line 126, in _get_response
    response = self.process_exception_by_middleware(e, request)
  File "C:\Users\ShadowMimosa\AppData\Local\Programs\Python\Python37\lib\site-packages\django\core\handlers\base.py", line 124, in _get_response
    response = wrapped_callback(request, *callback_args, **callback_kwargs)
  File "C:\Users\ShadowMimosa\Documents\GitRepository\HttpRunnerManager\HttpRunnerManager\activator.py", line 15, in process
    result = fun(request, index) if index else fun(request)
  File "C:\Users\ShadowMimosa\Documents\GitRepository\HttpRunnerManager\ApiManager\views.py", line 39, in wrapper
    return func(request, *args, **kwargs)
  File "C:\Users\ShadowMimosa\Documents\GitRepository\HttpRunnerManager\ApiManager\views.py", line 236, in run_test
    runner.run(testcase_dir_path)
  File "C:\Users\ShadowMimosa\AppData\Local\Programs\Python\Python37\lib\site-packages\httprunner\api.py", line 234, in run
    raise exceptions.ParamsError("invalid testcase path or testcases.")
httprunner.exceptions.ParamsError: invalid testcase path or testcases.
2018-12-21 10:27:13,194 [django.request:228] [log:log_response] [ERROR]- Internal Server Error: /api/run_test/
Traceback (most recent call last):
  File "C:\Users\ShadowMimosa\AppData\Local\Programs\Python\Python37\lib\site-packages\django\core\handlers\exception.py", line 34, in inner
    response = get_response(request)
  File "C:\Users\ShadowMimosa\AppData\Local\Programs\Python\Python37\lib\site-packages\django\core\handlers\base.py", line 126, in _get_response
    response = self.process_exception_by_middleware(e, request)
  File "C:\Users\ShadowMimosa\AppData\Local\Programs\Python\Python37\lib\site-packages\django\core\handlers\base.py", line 124, in _get_response
    response = wrapped_callback(request, *callback_args, **callback_kwargs)
  File "C:\Users\ShadowMimosa\Documents\GitRepository\HttpRunnerManager\HttpRunnerManager\activator.py", line 15, in process
    result = fun(request, index) if index else fun(request)
  File "C:\Users\ShadowMimosa\Documents\GitRepository\HttpRunnerManager\ApiManager\views.py", line 39, in wrapper
    return func(request, *args, **kwargs)
  File "C:\Users\ShadowMimosa\Documents\GitRepository\HttpRunnerManager\ApiManager\views.py", line 236, in run_test
    runner.run(testcase_dir_path)
  File "C:\Users\ShadowMimosa\AppData\Local\Programs\Python\Python37\lib\site-packages\httprunner\api.py", line 234, in run
    raise exceptions.ParamsError("invalid testcase path or testcases.")
httprunner.exceptions.ParamsError: invalid testcase path or testcases.
2018-12-21 10:28:52,726 [django.request:228] [log:log_response] [ERROR]- Internal Server Error: /api/run_test/
Traceback (most recent call last):
  File "C:\Users\ShadowMimosa\AppData\Local\Programs\Python\Python37\lib\site-packages\django\core\handlers\exception.py", line 34, in inner
    response = get_response(request)
  File "C:\Users\ShadowMimosa\AppData\Local\Programs\Python\Python37\lib\site-packages\django\core\handlers\base.py", line 126, in _get_response
    response = self.process_exception_by_middleware(e, request)
  File "C:\Users\ShadowMimosa\AppData\Local\Programs\Python\Python37\lib\site-packages\django\core\handlers\base.py", line 124, in _get_response
    response = wrapped_callback(request, *callback_args, **callback_kwargs)
  File "C:\Users\ShadowMimosa\Documents\GitRepository\HttpRunnerManager\HttpRunnerManager\activator.py", line 15, in process
    result = fun(request, index) if index else fun(request)
  File "C:\Users\ShadowMimosa\Documents\GitRepository\HttpRunnerManager\ApiManager\views.py", line 39, in wrapper
    return func(request, *args, **kwargs)
  File "C:\Users\ShadowMimosa\Documents\GitRepository\HttpRunnerManager\ApiManager\views.py", line 236, in run_test
    runner.run(testcase_dir_path)
  File "C:\Users\ShadowMimosa\AppData\Local\Programs\Python\Python37\lib\site-packages\httprunner\api.py", line 234, in run
    raise exceptions.ParamsError("invalid testcase path or testcases.")
httprunner.exceptions.ParamsError: invalid testcase path or testcases.
2018-12-21 10:29:10,489 [django.request:228] [log:log_response] [ERROR]- Internal Server Error: /api/run_test/
Traceback (most recent call last):
  File "C:\Users\ShadowMimosa\AppData\Local\Programs\Python\Python37\lib\site-packages\django\core\handlers\exception.py", line 34, in inner
    response = get_response(request)
  File "C:\Users\ShadowMimosa\AppData\Local\Programs\Python\Python37\lib\site-packages\django\core\handlers\base.py", line 126, in _get_response
    response = self.process_exception_by_middleware(e, request)
  File "C:\Users\ShadowMimosa\AppData\Local\Programs\Python\Python37\lib\site-packages\django\core\handlers\base.py", line 124, in _get_response
    response = wrapped_callback(request, *callback_args, **callback_kwargs)
  File "C:\Users\ShadowMimosa\Documents\GitRepository\HttpRunnerManager\HttpRunnerManager\activator.py", line 15, in process
    result = fun(request, index) if index else fun(request)
  File "C:\Users\ShadowMimosa\Documents\GitRepository\HttpRunnerManager\ApiManager\views.py", line 39, in wrapper
    return func(request, *args, **kwargs)
  File "C:\Users\ShadowMimosa\Documents\GitRepository\HttpRunnerManager\ApiManager\views.py", line 236, in run_test
    runner.run(testcase_dir_path)
  File "C:\Users\ShadowMimosa\AppData\Local\Programs\Python\Python37\lib\site-packages\httprunner\api.py", line 234, in run
    raise exceptions.ParamsError("invalid testcase path or testcases.")
httprunner.exceptions.ParamsError: invalid testcase path or testcases.
2018-12-21 10:29:17,536 [django.request:228] [log:log_response] [ERROR]- Internal Server Error: /api/run_test/
Traceback (most recent call last):
  File "C:\Users\ShadowMimosa\AppData\Local\Programs\Python\Python37\lib\site-packages\django\core\handlers\exception.py", line 34, in inner
    response = get_response(request)
  File "C:\Users\ShadowMimosa\AppData\Local\Programs\Python\Python37\lib\site-packages\django\core\handlers\base.py", line 126, in _get_response
    response = self.process_exception_by_middleware(e, request)
  File "C:\Users\ShadowMimosa\AppData\Local\Programs\Python\Python37\lib\site-packages\django\core\handlers\base.py", line 124, in _get_response
    response = wrapped_callback(request, *callback_args, **callback_kwargs)
  File "C:\Users\ShadowMimosa\Documents\GitRepository\HttpRunnerManager\HttpRunnerManager\activator.py", line 15, in process
    result = fun(request, index) if index else fun(request)
  File "C:\Users\ShadowMimosa\Documents\GitRepository\HttpRunnerManager\ApiManager\views.py", line 39, in wrapper
    return func(request, *args, **kwargs)
  File "C:\Users\ShadowMimosa\Documents\GitRepository\HttpRunnerManager\ApiManager\views.py", line 236, in run_test
    runner.run(testcase_dir_path)
  File "C:\Users\ShadowMimosa\AppData\Local\Programs\Python\Python37\lib\site-packages\httprunner\api.py", line 234, in run
    raise exceptions.ParamsError("invalid testcase path or testcases.")
httprunner.exceptions.ParamsError: invalid testcase path or testcases.
2018-12-21 10:29:25,654 [django.request:228] [log:log_response] [ERROR]- Internal Server Error: /api/run_batch_test/
Traceback (most recent call last):
  File "C:\Users\ShadowMimosa\AppData\Local\Programs\Python\Python37\lib\site-packages\django\core\handlers\exception.py", line 34, in inner
    response = get_response(request)
  File "C:\Users\ShadowMimosa\AppData\Local\Programs\Python\Python37\lib\site-packages\django\core\handlers\base.py", line 126, in _get_response
    response = self.process_exception_by_middleware(e, request)
  File "C:\Users\ShadowMimosa\AppData\Local\Programs\Python\Python37\lib\site-packages\django\core\handlers\base.py", line 124, in _get_response
    response = wrapped_callback(request, *callback_args, **callback_kwargs)
  File "C:\Users\ShadowMimosa\Documents\GitRepository\HttpRunnerManager\HttpRunnerManager\activator.py", line 15, in process
    result = fun(request, index) if index else fun(request)
  File "C:\Users\ShadowMimosa\Documents\GitRepository\HttpRunnerManager\ApiManager\views.py", line 39, in wrapper
    return func(request, *args, **kwargs)
  File "C:\Users\ShadowMimosa\Documents\GitRepository\HttpRunnerManager\ApiManager\views.py", line 277, in run_batch_test
    runner.run(testcase_dir_path)
  File "C:\Users\ShadowMimosa\AppData\Local\Programs\Python\Python37\lib\site-packages\httprunner\api.py", line 234, in run
    raise exceptions.ParamsError("invalid testcase path or testcases.")
httprunner.exceptions.ParamsError: invalid testcase path or testcases.
2018-12-21 10:30:41,161 [HttpRunnerManager:110] [operation:add_module_data] [INFO]- 模块添加成功：{'module_name': 'likes', 'test_user': 'admin', 'simple_desc': "Tumblr's likes", 'other_desc': '', 'belong_project': <ProjectInfo: ProjectInfo object (2)>}
2018-12-21 10:34:23,095 [HttpRunnerManager:55] [views:login] [INFO]- admin 登录成功
2018-12-21 10:37:14,404 [HttpRunnerManager:154] [operation:add_case_data] [INFO]- tumblr's likes用例添加成功: {'test': {'request': {'url': 'https://api.tumblr.com/v2/blog/luckoooo/likes', 'method': 'GET', 'params': {'api_key': 'o25lc4XecQpXpoEIhoUu8AD2MMmQu3xXJLm9J6n2z6XH3wqwUK'}}, 'name': "tumblr's likes"}}
